<?xml version="1.0"?>
<!-- This sdf file is based on schunk_wsg_50.sdf -->
<sdf version="1.7">
  <model name="final_gripper">
    <!-- body link -->
    <link name="body_gripper">
      <pose>0 0 0 0 0 0</pose>
      <inertial> 
        <pose>4.03E-06 1.08E-05 0.04139748 0 0 0</pose>
        <mass>0.988882</mass>
        <inertia>
          <ixx>0.00011614</ixx>
          <ixy>1E-08</ixy>
          <ixz>4E-08</ixz>
          <iyy>0.00010327</iyy>
          <iyz>0</iyz>
          <izz>9.707E-05</izz>
        </inertia>
      </inertial>
      <kinematic>0</kinematic>
      <visual name="visual">
        <geometry>
          <mesh>
            <scale>1 1 1</scale>
            <uri>base_gripper.gltf</uri>
          </mesh>
        </geometry>
      </visual>
      <collision name="collision">
        <pose>0 0 0.039 0 0 0</pose>
        <!-- Collision geometry
        <geometry>
          <box>
            <size>0.07 0.09 0.08</size>
          </box>
        </geometry>-->
        <drake:proximity_properties>
          <drake:compliant_hydroelastic/>
          <drake:hydroelastic_modulus>1.0e6</drake:hydroelastic_modulus>
        </drake:proximity_properties>
      </collision>
    </link>

    <!-- left_finger link -->
    <link name="left_finger">
      <pose>0 0.04 0.070003 0 0 0</pose>
      <inertial>
        <mass>0.05</mass>
        <inertia>
          <ixx>0.16</ixx>
          <ixy>0</ixy>
          <ixz>0</ixz>
          <iyy>0.16</iyy>
          <iyz>0</iyz>
          <izz>0.16</izz>
        </inertia>
      </inertial>
      <kinematic>0</kinematic>
      <visual name="visual">
        <geometry>
          <mesh>
            <scale>1 1 1</scale>
            <uri>left_finger.gltf</uri>
          </mesh>
        </geometry>
      </visual>
      <collision name="collision">
        <pose>0 0.03 0.05 0 0 0</pose>
        <geometry>
          <box>
            <size>0.025 0.02 0.07</size>
          </box>
        </geometry>
        <drake:proximity_properties>
          <drake:compliant_hydroelastic/>
          <drake:mu_dynamic>1.0</drake:mu_dynamic>
          <drake:hydroelastic_modulus>1.0e6</drake:hydroelastic_modulus>
        </drake:proximity_properties>
      </collision>
    </link>


    <!-- right_finger link -->
    <link name="right_finger">
      <pose>0 -0.04 0.070003 0 0 0</pose>
      <inertial>
        <mass>0.05</mass>
        <inertia>
          <ixx>0.16</ixx>
          <ixy>0</ixy>
          <ixz>0</ixz>
          <iyy>0.16</iyy>
          <iyz>0</iyz>
          <izz>0.16</izz>
        </inertia>
      </inertial>
      <kinematic>0</kinematic>
      <visual name="visual">
        <geometry>
          <mesh>
            <scale>1 1 1</scale>
            <uri>right_finger.gltf</uri>
          </mesh>
        </geometry>
        <material>
          <diffuse>0.2 0.2 0.2 1</diffuse>
        </material>
      </visual>
      <collision name="collision">
        <pose>0 -0.03 0.05 0 0 0</pose>
        <geometry>
          <box>
            <size>0.025 0.02 0.07</size>
          </box>
        </geometry>
        <drake:proximity_properties>
          <drake:compliant_hydroelastic/>
          <drake:mu_dynamic>1.0</drake:mu_dynamic>
          <drake:hydroelastic_modulus>1.0e6</drake:hydroelastic_modulus>
        </drake:proximity_properties>
      </collision>
    </link>

    <!-- left_finger joint-->
    <joint name="left_finger_sliding_joint" type="prismatic">
      <parent>body_gripper</parent>
      <child>left_finger</child>
      <axis>
        <xyz>0 1 0</xyz>
        <!-- Drake attaches an actuator to all and only joints with a nonzero
             effort limit. -->
        <limit>
          <lower>-0.05</lower>
          <upper>0</upper>
          <effort>80</effort>
          <stiffness>15000</stiffness>
          <velocity>0.35</velocity>
        </limit>
        <dynamics>
          <spring_reference>0</spring_reference>
          <spring_stiffness>0</spring_stiffness>
          <damping>0</damping>
          <friction>0</friction>
        </dynamics>
      </axis>
    </joint>

    <!-- right_finger_joint -->
    <joint name="right_finger_sliding_joint" type="prismatic">
      <parent>body_gripper</parent>
      <child>right_finger</child>
      <axis>
        <xyz>0 1 0</xyz>
        <!-- Drake attaches an actuator to all and only joints with a nonzero
             effort limit. -->
        <limit>
          <lower>0</lower>
          <upper>0.05</upper>
          <effort>80</effort>
          <stiffness>15000</stiffness>
          <velocity>0.35</velocity>
        </limit>
        <dynamics>
          <spring_reference>0</spring_reference>
          <spring_stiffness>0</spring_stiffness>
          <damping>0</damping>
          <friction>0</friction>
        </dynamics>
      </axis>
    </joint>

    <!-- END_EFFECTOR Tool Center Point-->
      <link name="tool_center_point">
        <pose>0 0 0.13 0 0 0</pose>
      </link>

      <joint name="tool_center_point_fixed_joint" type="fixed">
        <parent>body_gripper</parent>
        <child>tool_center_point</child>
      </joint>

    <static>0</static>

  </model>
</sdf>
